Workbook
Name NativeTimeline_Date: #N/A
Name Slicer_Customer_Segment: #N/A
Name Slicer_Product_Name: #N/A

Sheet Worksheet
A1: Txn No | B1: Date | C1: Month | D1: Customer Id | E1: Product Id | F1: Product Name | G1: Price | H1: Quantity | I1: Total Sales | J1: Country | K1: Customer Segment
A2: TXN001 | B2: 45659 | C2: Jan | D2: C001 | E2: P001 | F2: Laptop | G2: 350000 | H2: 1 | I2: 350000 | J2: Nigeria | K2: =VLOOKUP(sales_dataset[[#This Row],[Customer Id]],Analysis!$F$34:$L$41,7,FALSE) -> VIP
A3: TXN002 | B3: 45659 | C3: Jan | D3: C002 | E3: P002 | F3: Phone | G3: 180000 | H3: 2 | I3: 360000 | J3: Nigeria | K3: =VLOOKUP(sales_dataset[[#This Row],[Customer Id]],Analysis!$F$34:$L$41,7,FALSE) -> VIP
A4: TXN003 | B4: 45660 | C4: Jan | D4: C003 | E4: P003 | F4: Headphones | G4: 25000 | H4: 3 | I4: 75000 | J4: Nigeria | K4: =VLOOKUP(sales_dataset[[#This Row],[Customer Id]],Analysis!$F$34:$L$41,7,FALSE) -> VIP
A5: TXN004 | B5: 45662 | C5: Jan | D5: C001 | E5: P004 | F5: Mouse | G5: 8000 | H5: 2 | I5: 16000 | J5: Nigeria | K5: =VLOOKUP(sales_dataset[[#This Row],[Customer Id]],Analysis!$F$34:$L$41,7,FALSE) -> VIP
A6: TXN005 | B6: 45663 | C6: Jan | D6: C004 | E6: P002 | F6: Phone | G6: 180000 | H6: 1 | I6: 180000 | J6: Nigeria | K6: =VLOOKUP(sales_dataset[[#This Row],[Customer Id]],Analysis!$F$34:$L$41,7,FALSE) -> Regular
A7: TXN006 | B7: 45667 | C7: Jan | D7: C002 | E7: P005 | F7: Keyboard | G7: 15000 | H7: 2 | I7: 30000 | J7: Nigeria | K7: =VLOOKUP(sales_dataset[[#This Row],[Customer Id]],Analysis!$F$34:$L$41,7,FALSE) -> VIP
A8: TXN007 | B8: 45690 | C8: Feb | D8: C005 | E8: P001 | F8: Laptop | G8: 350000 | H8: 1 | I8: 350000 | J8: Nigeria | K8: =VLOOKUP(sales_dataset[[#This Row],[Customer Id]],Analysis!$F$34:$L$41,7,FALSE) -> High Value
A9: TXN008 | B9: 45692 | C9: Feb | D9: C003 | E9: P002 | F9: Phone | G9: 180000 | H9: 1 | I9: 180000 | J9: Nigeria | K9: =VLOOKUP(sales_dataset[[#This Row],[Customer Id]],Analysis!$F$34:$L$41,7,FALSE) -> VIP
A10: TXN009 | B10: 45694 | C10: Feb | D10: C006 | E10: P006 | F10: Monitor | G10: 120000 | H10: 2 | I10: 240000 | J10: Nigeria | K10: =VLOOKUP(sales_dataset[[#This Row],[Customer Id]],Analysis!$F$34:$L$41,7,FALSE) -> Regular
A11: TXN010 | B11: 45698 | C11: Feb | D11: C002 | E11: P003 | F11: Headphones | G11: 25000 | H11: 4 | I11: 100000 | J11: Nigeria | K11: =VLOOKUP(sales_dataset[[#This Row],[Customer Id]],Analysis!$F$34:$L$41,7,FALSE) -> VIP
A12: TXN011 | B12: 45700 | C12: Feb | D12: C001 | E12: P002 | F12: Phone | G12: 180000 | H12: 1 | I12: 180000 | J12: Nigeria | K12: =VLOOKUP(sales_dataset[[#This Row],[Customer Id]],Analysis!$F$34:$L$41,7,FALSE) -> VIP
A13: TXN012 | B13: 45717 | C13: Mar | D13: C007 | E13: P004 | F13: Mouse | G13: 8000 | H13: 5 | I13: 40000 | J13: Nigeria | K13: =VLOOKUP(sales_dataset[[#This Row],[Customer Id]],Analysis!$F$34:$L$41,7,FALSE) -> Low Value
... A21: TXN020 | B21: 45752 | C21: Apr | D21: C003 | E21: P004 | F21: Mouse | G21: 8000 | H21: 4 | I21: 32000 | J21: Nigeria | K21: =VLOOKUP(sales_dataset[[#This Row],[Customer Id]],Analysis!$F$34:$L$41,7,FALSE) -> VIP

Sheet Analysis
A2: Revenue | B2: Quantity Sold | C2: Customers No | D2: Average Order Value
A3: 3588000 | B3: 40 | C3: 8 | D3: 179400
A4: =A3 -> 3588000 | B4: =B3 -> 40 | C4: =C3 -> 8 | D4: =D3 -> 179400
A7: Time Analysis | D7: Product Analysis | G7: Quantity Analysis | J7: Customer ID by Txns count | N7: Quantity Sold per Product
A8: Month | B8: Sum of Total_Sales | D8: Product_Name | E8: Sum of Total_Sales | G8: Txn_No | H8: Average of Quantity | J8: Customer_Id | K8: Count of Txn_No | N8: Product_Name | O8: Sum of Quantity
A9: Jan | B9: 1011000 | D9: Headphones | E9: 225000 | G9: TXN001 | H9: 1 | J9: C001 | K9: 4 | N9: Headphones | O9: 9
A10: Feb | B10: 1050000 | D10: Laptop | E10: 1400000 | G10: TXN002 | H10: 2 | J10: C002 | K10: 4 | N10: Keyboard | O10: 5
A11: Mar | B11: 965000 | D11: Monitor | E11: 360000 | G11: TXN003 | H11: 3 | J11: C003 | K11: 4 | N11: Laptop | O11: 4
A12: Apr | B12: 562000 | D12: Mouse | E12: 88000 | G12: TXN004 | H12: 2 | J12: C004 | K12: 2 | N12: Monitor | O12: 3
D13: Phone | E13: 1440000 | G13: TXN005 | H13: 1 | J13: C005 | K13: 2 | N13: Mouse | O13: 11
G14: TXN006 | H14: 2 | J14: C006 | K14: 2 | N14: Phone | O14: 8
G15: TXN007 | H15: 1 | J15: C007 | K15: 1
G16: TXN008 | H16: 1 | J16: C008 | K16: 1
G17: TXN009 | H17: 2
A18: Customer Analysis | G18: TXN010 | H18: 4
A19: Customer_Id | B19: Sum of Total_Sales | G19: TXN011 | H19: 1
A20: C008 | B20: 180000 | G20: TXN012 | H20: 5
A21: C007 | B21: 40000 | G21: TXN013 | H21: 1
A22: C006 | B22: 290000 | G22: TXN014 | H22: 1
A23: C005 | B23: 395000 | G23: TXN015 | H23: 2
A24: C004 | B24: 300000 | G24: TXN016 | H24: 3
A25: C003 | B25: 637000 | G25: TXN017 | H25: 2
A26: C002 | B26: 850000 | G26: TXN018 | H26: 1
A27: C001 | B27: 896000 | G27: TXN019 | H27: 1
G28: TXN020 | H28: 4
A32: Customer Representation | F32: Customer Segmentation
A33: Customer_Id | B33: Count of Txn_No | C33: Sum of Total_Sales | F33: Customer_Id | G33: Txn_Count | H33: Total_Sales | I33: Frequency Score | J33: Monetary Score | K33: Combo | L33: Customer Segment
A34: C001 | B34: 4 | C34: 896000 | F34: =$A$34:$A$41 -> C001 | G34: =$B$34:$B$41 -> 4 | H34: =$C$34:$C$41 -> 896000 | I34: =IF(B34<=1, "Low", IF(B34<=3, "Medium","High")) -> High | J34: =IF(C34<100000, "Low", IF(C34<=300000, "Medium", "High")) -> High | K34: =I34 & "-" & J34 -> High-High | L34: =IF(AND(Table2[[#This Row],[Combo]] = "High-High"),"VIP",IF(AND(Table2[[#This Row],[Combo]] = "Medium-High"),"High Value",IF(AND(Table2[[#This Row],[Combo]] = "Medium-Medium"),"Regular",IF(AND(Table2[[#This Row],[Combo]] = "Low-Medium"),"At Risk", "Low Value")))) -> VIP
A35: C002 | B35: 4 | C35: 850000 | F35: =$A$34:$A$41 -> C002 | G35: =$B$34:$B$41 -> 4 | H35: =$C$34:$C$41 -> 850000 | I35: =IF(B35<=1, "Low", IF(B35<=3, "Medium","High")) -> High | J35: =IF(C35<100000, "Low", IF(C35<=300000, "Medium", "High")) -> High | K35: =I35 & "-" & J35 -> High-High | L35: =IF(AND(Table2[[#This Row],[Combo]] = "High-High"),"VIP",IF(AND(Table2[[#This Row],[Combo]] = "Medium-High"),"High Value",IF(AND(Table2[[#This Row],[Combo]] = "Medium-Medium"),"Regular",IF(AND(Table2[[#This Row],[Combo]] = "Low-Medium"),"At Risk", "Low Value")))) -> VIP
A36: C003 | B36: 4 | C36: 637000 | F36: =$A$34:$A$41 -> C003 | G36: =$B$34:$B$41 -> 4 | H36: =$C$34:$C$41 -> 637000 | I36: =IF(B36<=1, "Low", IF(B36<=3, "Medium","High")) -> High | J36: =IF(C36<100000, "Low", IF(C36<=300000, "Medium", "High")) -> High | K36: =I36 & "-" & J36 -> High-High | L36: =IF(AND(Table2[[#This Row],[Combo]] = "High-High"),"VIP",IF(AND(Table2[[#This Row],[Combo]] = "Medium-High"),"High Value",IF(AND(Table2[[#This Row],[Combo]] = "Medium-Medium"),"Regular",IF(AND(Table2[[#This Row],[Combo]] = "Low-Medium"),"At Risk", "Low Value")))) -> VIP
A37: C004 | B37: 2 | C37: 300000 | F37: =$A$34:$A$41 -> C004 | G37: =$B$34:$B$41 -> 2 | H37: =$C$34:$C$41 -> 300000 | I37: =IF(B37<=1, "Low", IF(B37<=3, "Medium","High")) -> Medium | J37: =IF(C37<100000, "Low", IF(C37<=300000, "Medium", "High")) -> Medium | K37: =I37 & "-" & J37 -> Medium-Medium | L37: =IF(AND(Table2[[#This Row],[Combo]] = "High-High"),"VIP",IF(AND(Table2[[#This Row],[Combo]] = "Medium-High"),"High Value",IF(AND(Table2[[#This Row],[Combo]] = "Medium-Medium"),"Regular",IF(AND(Table2[[#This Row],[Combo]] = "Low-Medium"),"At Risk", "Low Value")))) -> Regular
A38: C005 | B38: 2 | C38: 395000 | F38: =$A$34:$A$41 -> C005 | G38: =$B$34:$B$41 -> 2 | H38: =$C$34:$C$41 -> 395000 | I38: =IF(B38<=1, "Low", IF(B38<=3, "Medium","High")) -> Medium | J38: =IF(C38<100000, "Low", IF(C38<=300000, "Medium", "High")) -> High | K38: =I38 & "-" & J38 -> Medium-High | L38: =IF(AND(Table2[[#This Row],[Combo]] = "High-High"),"VIP",IF(AND(Table2[[#This Row],[Combo]] = "Medium-High"),"High Value",IF(AND(Table2[[#This Row],[Combo]] = "Medium-Medium"),"Regular",IF(AND(Table2[[#This Row],[Combo]] = "Low-Medium"),"At Risk", "Low Value")))) -> High Value
A39: C006 | B39: 2 | C39: 290000 | F39: =$A$34:$A$41 -> C006 | G39: =$B$34:$B$41 -> 2 | H39: =$C$34:$C$41 -> 290000 | I39: =IF(B39<=1, "Low", IF(B39<=3, "Medium","High")) -> Medium | J39: =IF(C39<100000, "Low", IF(C39<=300000, "Medium", "High")) -> Medium | K39: =I39 & "-" & J39 -> Medium-Medium | L39: =IF(AND(Table2[[#This Row],[Combo]] = "High-High"),"VIP",IF(AND(Table2[[#This Row],[Combo]] = "Medium-High"),"High Value",IF(AND(Table2[[#This Row],[Combo]] = "Medium-Medium"),"Regular",IF(AND(Table2[[#This Row],[Combo]] = "Low-Medium"),"At Risk", "Low Value")))) -> Regular
A40: C007 | B40: 1 | C40: 40000 | F40: =$A$34:$A$41 -> C007 | G40: =$B$34:$B$41 -> 1 | H40: =$C$34:$C$41 -> 40000 | I40: =IF(B40<=1, "Low", IF(B40<=3, "Medium","High")) -> Low | J40: =IF(C40<100000, "Low", IF(C40<=300000, "Medium", "High")) -> Low | K40: =I40 & "-" & J40 -> Low-Low | L40: =IF(AND(Table2[[#This Row],[Combo]] = "High-High"),"VIP",IF(AND(Table2[[#This Row],[Combo]] = "Medium-High"),"High Value",IF(AND(Table2[[#This Row],[Combo]] = "Medium-Medium"),"Regular",IF(AND(Table2[[#This Row],[Combo]] = "Low-Medium"),"At Risk", "Low Value")))) -> Low Value
A41: C008 | B41: 1 | C41: 180000 | F41: =$A$34:$A$41 -> C008 | G41: =$B$34:$B$41 -> 1 | H41: =$C$34:$C$41 -> 180000 | I41: =IF(B41<=1, "Low", IF(B41<=3, "Medium","High")) -> Low | J41: =IF(C41<100000, "Low", IF(C41<=300000, "Medium", "High")) -> Medium | K41: =I41 & "-" & J41 -> Low-Medium | L41: =IF(AND(Table2[[#This Row],[Combo]] = "High-High"),"VIP",IF(AND(Table2[[#This Row],[Combo]] = "Medium-High"),"High Value",IF(AND(Table2[[#This Row],[Combo]] = "Medium-Medium"),"Regular",IF(AND(Table2[[#This Row],[Combo]] = "Low-Medium"),"At Risk", "Low Value")))) -> At Risk
F44: Customer Per Segment | I44: Revenue Per Segment
F45: Customer Segment | G45: Count of Customer_Id | I45: Customer Segment | J45: Sum of Total_Sales
F46: VIP | G46: 3 | I46: VIP | J46: 2383000
F47: Regular | G47: 2 | I47: Regular | J47: 590000
F48: Low Value | G48: 1 | I48: Low Value | J48: 40000
...

Sheet Dashboard
